# 1-2. catch문

## ✏️  Catch문

- `catch` 에는 예외 타입을 인자로 갖으며, 예외가 발생했을 때 수행될 코드를 작성한다
- JVM은 버그가 발생하면 발생한 예외 타입으로 객체를 생성한다. 생성된 객체를  catch block의 인자로 받아온다
- catch문은 인자값의 예외 타입을 다르게 하여 여러개 작성할 수 있다.
- catch문은 자식 → 부모 순으로 작성해야한다 / 그렇지 않으면 여러개의 catch문이 실행될 수 있기 때문이다
- 여러개의 catch문 중, JVM이 전달한 예외 타입과 동일한 인자를 가진 catch문 하나만이 실행된다
- 만약 예외타입과 동일한 인자를 가지는 catch문이 없다면 프로그램은 비정상 종료하게 된다
- catch문에는 예외에 대한 설명을 출력하는 `e.printStackTrace()` , `e.getMessage()` 를 사용하기도 한다
    - `e.printStackTrace()` 는 자체적으로 출력해주는 메서드
    - `e.getMessage()` 는 자체적으로 출력하지 못하므로 sysout안에서 출력해주어야한다
    - 일반적으로 예외 발생 원인을 메세지를 출력하므로 catch문에서 사용한다 / [자세히 알아보기](4-1%20%E1%84%8B%E1%85%A8%E1%84%8B%E1%85%AC%20%E1%84%87%E1%85%A1%E1%86%AF%E1%84%89%E1%85%A2%E1%86%BC%20%E1%84%8B%E1%85%AF%E1%86%AB%E1%84%8B%E1%85%B5%E1%86%AB%20%E1%84%86%E1%85%A6%E1%84%89%E1%85%A6%E1%84%8C%E1%85%B5%E1%84%85%E1%85%B3%E1%86%AF%20%E1%84%8E%E1%85%AE%E1%86%AF%E1%84%85%E1%85%A7%E1%86%A8%E1%84%92%E1%85%A1%E1%84%82%E1%85%B3%E1%86%AB%20%E1%84%87%E1%85%A1%E1%86%BC%E1%84%87%E1%85%A5%20b654abd28e7d48cc97ad99fe25e52c43.md)

## ✏️  Catch문을 여러개 사용할 수 있다

```java
package exception.runtime.test;

public class RuntimeExceptionTest2 {

	public static void main(String[] args) {	
		String[] str = {
				"Hello JAVA",
				"No, I Mean it",
				"Nice to meet you"
		};
		
		int i = 0;
		while(i <= 3) {
			try {
				System.out.println(str[i++]);
			}catch(NullPointerException e){
				System.out.println("Nice Catch / 1.NullPointerException");
			}catch(ArithmeticException e){
				System.out.println("Nice Catch / 2.ArithmeticException");
			}catch(ArrayIndexOutOfBoundsException e){
				System.out.println("Nice Catch / 3.ArrayIndexOutOfBoundsException");
			}
		}
		System.out.println("while loop the end");
	}
}
```

- catch문은 인자값의 예외 타입을 다르게 하여 여러개 작성할 수 있다.
- 여러개의 catch문 중, JVM이 전달한 예외 타입과 동일한 인자를 가진 catch문 하나만이 실행된다
- 만약 예외타입과 동일한 인자를 가지는 catch문이 없다면 프로그램은 비정상 종료하게 된다

## ✏️  여러 개 Catch문 사용 시 주의 사항

```java
package exception.runtime.test;

public class RuntimeExceptionTest4 {

	public static void main(String[] args) {	
		String[] str = {
				"Hello JAVA",
				"No, I Mean it",
				"Nice to meet you"
		};
		
		int i = 0;
		while(i <= 3) {
			try {
				System.out.println(str[i++]);
			}catch(Exception e){
				System.out.println("Nice Catch / 1.NullPointerException");
			**}catch(ArrayIndexOutOfBoundsException e){
				System.out.println("Nice Catch / 2.ArrayIndexOutOfBoundsException");
			}**
		}
		System.out.println("while loop the end");
	}
}
```

- catch문은 자식 → 부모 순으로 작성해야한다
- 그렇지 않으면 여러개의 catch문이 실행될 수 있기 때문에 에러가 발생한다
- 순서를 아래와 같이 수정해주어야 에러가 발생하지 않는다
    
    ```java
    try {
    	System.out.println(str[i++]);
    }catch(ArrayIndexOutOfBoundsException e){
    	System.out.println("Nice Catch / 2.ArrayIndexOutOfBoundsException");
    }catch(Exception e){
    	System.out.println("Nice Catch / 1.NullPointerException");
    }
    ```