# 4. 사용자 정의 Exception

## ✏️  사용자 정의 Exception

1. 어떤 특정 조건에 고의적으로 예외를 발생시키는 것도 사용자 정의 Exception이다
2. 개발자는 스스로 Exception 클래스를 정의해서 사용할 수 있다. 이러한 Exception을 사용자 정의 Exception이라고 한다

## ✏️  사용자 정의 Exception 특징

- 사용자 정의 Exception은 하나의 강력한 제어문으로 사용된다
- Java는 예외 역시 객체로 처리한다. 예외가 발생하면 JVM이 예외 객체를 만들어 던져준다
- 사용자 정의 Exception을 사용할 때에는 예외 객체를 사용자가 만들어 사용한다
- 그리고 사용자 정의 예외는  `throw` 키워드와 함께 예외 객체를 생성한다

## ✏️  사용자 정의 Exception : Case(1)

- 어떤 특정 조건에 고의적으로 예외를 발생시키는 것을 의미한다
- 아래의 예제에서는 이미 존재하는 Exception을 고의적으로 발생시켰다
- 사용자가 정의한 Exception클래스를 사용하여 예외처리를 할수도있다 (Case2)

```java
package exception.user.test;

class User{
	public void go() throws ArithmeticException{
		int i = 10;
		int j = 0;
		System.out.println("1. i/j 연산 진행");
		if(j==0) {
			throw new ArithmeticException();
			// ArithmeticException : 나누기 연산 중, 분모가 0인경우 발생하는 예외 
		}
	}
}

public class UserExceptionTest1 {
	public static void main(String[] args) {
		User user = new User();
		System.out.println("2. go() 호출");
		user.go();
		System.out.println("3. 프로그램 종료");
	}

}
```

![image](img/04-1.png)

- 고의적으로 ArithmeticException 을 발생시켰다
- 예외 처리를 하지는 않았으므로 프로그램이 비정상 종료된다
- 메서드 내부에서의 예외는 메서드 내부에서 직접다루는 것보다 메인 메서드로 던져서 처리하는 것이 좋다

```java
package exception.user.test;

class User{
	public void go() **throws ArithmeticException** {
		int i = 10;
		int j = 0;
		System.out.println("1. i/j 연산 진행");
		if(j==0) {
			throw new ArithmeticException();
			// ArithmeticException : 나누기 연산 중, 분모가 0인경우 발생하는 예외 
		}
	}
}

public class UserExceptionTest1 {
	public static void main(String[] args) {
		User user = new User();
		System.out.println("2. go() 호출");
		**try {
			user.go();			
		}catch(ArithmeticException e){
			System.out.println("폭탄 처리완료");
		}**
		System.out.println("3. 프로그램 종료");
	}

}
```

![image](img/04-2.png)

- 메서드 내부의 예외는 메서드 내부에서 직접 처리하지 않고 throws 키워드와 함께 호출 장소로 던져준다
- 메인 메서드에 던저진 예외는 메인 메서드에서 try-chatch문을 사용해 예외 처리한다

## ✏️  사용자 정의 Exception : Case(2)

- 개발자는 스스로 Exception 클래스를 정의해서 사용할 수 있다. 이러한 Exception을 사용자 정의 Exception이라고 한다
- 일반 클래스를 Exception 클래스로 정의하려면 Exception 클래스를 상속받는다

```java
package exception.user.test;

// 직접 만든 Exception 
class ZeroDevide **extends Exception{**
	public ZeroDevide() {
		this("this is zeroDevide Exception");
	}
	
	public ZeroDevide(String str) {
		super(str);
	}
}

class User{
	public void go() throws **ZeroDevide** {
		int i = 10;
		int j = 0;
		System.out.println("1. i/j 연산 진행");
		if(j==0) {
			throw new **ZeroDevide**();
			// ArithmeticException : 나누기 연산 중, 분모가 0인경우 발생하는 예외 
		}
	}
}

public class UserExceptionTest1 {
	public static void main(String[] args) {
		User user = new User();
		System.out.println("2. go() 호출");
		try {
			user.go();			
		}catch(**ZeroDevide** e){
			System.out.println("폭탄 처리완료");
		}
		System.out.println("3. 프로그램 종료");
	}

}
```

- Case1의 ArithmeticException 대신 사용자가 직접 정의한 **ZeroDevide 예외를 사용해 예외처리 할 수 있다**